<mujoco model="cart">
    <compiler angle="radian" />
    <size njmax="500" nconmax="100" />
    <option timestep="0.01" />

    <asset>
        <texture type="skybox" builtin="gradient" rgb1=".3 .5 .7" rgb2="0 0 0" width="32" height="512"/>
        <texture name="grid" type="2d" builtin="checker" width="512" height="512" rgb1=".1 .2 .3" rgb2=".2 .3 .4"/>
        <material name="grid" texture="grid" texrepeat="1 1" texuniform="true" reflectance=".2"/>
    </asset>

	<actuator>
		<motor gear="1.0" joint="cart1" name="cart1" ctrllimited="true" ctrlrange="-20. 20."/>
	</actuator>    

    <worldbody>
        <body name="cart1" pos="0 0 0.">
            
            <geom mass="0.495" condim='1' size="0.05 0.05 0.05" type="box" rgba="0 0 0.8 1" />
            <joint type='slide' name='cart1' pos='0 0 0' axis="1 0 0" limited="false" range="-1.5 1.5"/>
            <body name="cart2" pos="0.4 0 0.0">
                <joint name="cart2" pos="0 0 0.0" axis="1 0 0" type='slide' stiffness='175.0' damping='5.0' />
                <geom mass='0.537' size="0.05 0.05 0.05" type="box" rgba="1 0 0 1" />
                <body name="pend" pos="0.0 -0.075 -0.325">
                    <joint name="pend" pos="0 0 0.325" axis="0 1 0" type='hinge' stiffness='0.' damping='0.' />
                    <geom mass='0.537' size="0.01 0.325" type="cylinder" rgba="1 0 0 1" />
                </body>  
            </body>          
        </body>
    
    </worldbody>

</mujoco>
